Workbook

Sheet Produits
A1: SAM'S CLUB × BENCH DAKAR — Prix alignés marché local −5% (21/07/2026)
A2: Taux F CFA / USD : | B2: 580 | C2: Cellules jaunes modifiables — tout se recalcule.
A3: Remise vs prix Dakar : | B3: 0.05 | C3: Prix YARAM = prix Dakar × (1 − remise), arrondi au 100 F. Si introuvable à Dakar : prix $ × coef (couvre fret + douane + marge), arrondi au 100 F.
A4: Coef. estimation si introuvable (F CFA par $) : | B4: 1100 | C4: Bench réalisé sur : Univers Cosmetix, Fabellashop, Pharmec, Nubian Beauty, Miftah, Sengarmi, Lunéa, Poudrine, Jumia, etc.
A6: Catégorie | B6: Produit | C6: Prix $ | D6: Prix Dakar (F) | E6: Source Dakar | F6: Match | G6: PRIX YARAM (F) | H6: Note /5 | I6: Avis | J6: Image | K6: Sam's Club
A7: cheveux | B7: Being CURL POWER Shampoo & Conditioner Duo, 12 fl. oz., 2 pk. | C7: 9.96 | F7: introuvable | G7: =IF(ISNUMBER(D7),ROUND(D7*(1-$B$3)/100,0)*100,IF(ISNUMBER(C7),ROUND(C7*$B$4/100,0)*100,"")) -> 11000 | H7: 4.6 | I7: 114 | J7: Image | K7: Produit
A8: cheveux | B8: Being NOURISH + SHINE Shampoo & Conditioner Duo, 12 fl. oz., 2 pk. | C8: 9.96 | F8: introuvable | G8: =IF(ISNUMBER(D8),ROUND(D8*(1-$B$3)/100,0)*100,IF(ISNUMBER(C8),ROUND(C8*$B$4/100,0)*100,"")) -> 11000 | H8: 4.6 | I8: 110 | J8: Image | K8: Produit
A9: cheveux | B9: Davines This is a Medium Hair Spray Flexible Hold Styling, 12 fl. oz. | C9: 34.98 | F9: introuvable | G9: =IF(ISNUMBER(D9),ROUND(D9*(1-$B$3)/100,0)*100,IF(ISNUMBER(C9),ROUND(C9*$B$4/100,0)*100,"")) -> 38500 | J9: Image | K9: Produit
A10: cheveux | B10: Garnier Fructis Sleek & Shine Shampoo & Conditioner, 40 fl. oz., 2 pk. | C10: 17.78 | D10: 5000 | E10: Voir | F10: similaire | G10: =IF(ISNUMBER(D10),ROUND(D10*(1-$B$3)/100,0)*100,IF(ISNUMBER(C10),ROUND(C10*$B$4/100,0)*100,"")) -> 4800 | H10: 4.56 | I10: 482 | J10: Image | K10: Produit
A11: cheveux | B11: Hairmax Pro 12 LaserComb Hair Growth Bundle | C11: 171.75 | F11: introuvable | G11: =IF(ISNUMBER(D11),ROUND(D11*(1-$B$3)/100,0)*100,IF(ISNUMBER(C11),ROUND(C11*$B$4/100,0)*100,"")) -> 188900 | H11: 1 | I11: 1 | J11: Image | K11: Produit
A12: cheveux | B12: MONDAY Haircare ORIGINAL Dry Shampoo Trio, 5.1 oz., 3 pk. | C12: 14.98 | F12: introuvable | G12: =IF(ISNUMBER(D12),ROUND(D12*(1-$B$3)/100,0)*100,IF(ISNUMBER(C12),ROUND(C12*$B$4/100,0)*100,"")) -> 16500 | H12: 4.35 | I12: 156 | J12: Image | K12: Produit
A13: cheveux | B13: MONDAY Haircare SMOOTH Shampoo and Conditioner Set | C13: 21.87 | F13: introuvable | G13: =IF(ISNUMBER(D13),ROUND(D13*(1-$B$3)/100,0)*100,IF(ISNUMBER(C13),ROUND(C13*$B$4/100,0)*100,"")) -> 24100 | H13: 4.5 | I13: 281 | J13: Image | K13: Produit
A14: cheveux | B14: MONDAY Haircare ULTIMATE MOISTURE Gift Set | C14: 24 | F14: introuvable | G14: =IF(ISNUMBER(D14),ROUND(D14*(1-$B$3)/100,0)*100,IF(ISNUMBER(C14),ROUND(C14*$B$4/100,0)*100,"")) -> 26400 | H14: 4.4 | I14: 330 | J14: Image | K14: Produit
A15: cheveux | B15: Member's Mark Minoxidil 5% 120 Day Foam, 8.44 oz. | C15: 32.98 | F15: introuvable | G15: =IF(ISNUMBER(D15),ROUND(D15*(1-$B$3)/100,0)*100,IF(ISNUMBER(C15),ROUND(C15*$B$4/100,0)*100,"")) -> 36300 | H15: 3.71 | I15: 14 | J15: Image | K15: Produit
A16: cheveux | B16: Member's Mark Minoxidil 5%, Hair Regrowth Treatment for Men, 2 fl. oz., 6 ct. | C16: 19.98 | F16: introuvable | G16: =IF(ISNUMBER(D16),ROUND(D16*(1-$B$3)/100,0)*100,IF(ISNUMBER(C16),ROUND(C16*$B$4/100,0)*100,"")) -> 22000 | H16: 4.51 | I16: 676 | J16: Image | K16: Produit
A17: cheveux | B17: Men's Rogaine 5% Minoxidil Topical Hair Growth Treatment, 2 pack | C17: 91.98 | F17: introuvable | G17: =IF(ISNUMBER(D17),ROUND(D17*(1-$B$3)/100,0)*100,IF(ISNUMBER(C17),ROUND(C17*$B$4/100,0)*100,"")) -> 101200 | H17: 3.72 | I17: 648 | J17: Image | K17: Produit
A18: cheveux | B18: Mielle Rosemary Mint Scalp & Hair Strengthening Oil, 2 oz., 3 pk. | C18: 26.98 | D18: 9500 | E18: Voir | F18: similaire | G18: =IF(ISNUMBER(D18),ROUND(D18*(1-$B$3)/100,0)*100,IF(ISNUMBER(C18),ROUND(C18*$B$4/100,0)*100,"")) -> 9000 | H18: 4.67 | I18: 12 | J18: Image | K18: Produit
A19: cheveux | B19: Monday DEEP MOISTURE Hair Mask Duo, 8.4 fl. oz., 2 pk. | C19: 9.96 | F19: introuvable | G19: =IF(ISNUMBER(D19),ROUND(D19*(1-$B$3)/100,0)*100,IF(ISNUMBER(C19),ROUND(C19*$B$4/100,0)*100,"")) -> 11000 | H19: 4.44 | I19: 280 | J19: Image | K19: Produit
A20: cheveux | B20: NatureWell Living For Good Shampoo & Conditioner, 24 fl. oz., 2 pk. | C20: 27.98 | F20: introuvable | G20: =IF(ISNUMBER(D20),ROUND(D20*(1-$B$3)/100,0)*100,IF(ISNUMBER(C20),ROUND(C20*$B$4/100,0)*100,"")) -> 30800 | H20: 3.3 | I20: 40 | J20: Image | K20: Produit
A21: cheveux | B21: Nexxus Fullology Densifying Leave In Spray, 8 fl. oz. | C21: 16.98 | F21: introuvable | G21: =IF(ISNUMBER(D21),ROUND(D21*(1-$B$3)/100,0)*100,IF(ISNUMBER(C21),ROUND(C21*$B$4/100,0)*100,"")) -> 18700 | H21: 3.87 | I21: 93 | J21: Image | K21: Produit
A22: cheveux | B22: Nexxus Therappe Ultimate Moisturizing Shampoo, 42 fl. oz. | C22: Prix membre | F22: introuvable | G22: =IF(ISNUMBER(D22),ROUND(D22*(1-$B$3)/100,0)*100,IF(ISNUMBER(C22),ROUND(C22*$B$4/100,0)*100,"")) | H22: 4.7 | I22: 1150 | J22: Image | K22: Produit
A23: cheveux | B23: Pantene Pro-V Ultimate Care 3-in-1 Conditioner, 38.2 fl. oz. | C23: 7.98 | F23: introuvable | G23: =IF(ISNUMBER(D23),ROUND(D23*(1-$B$3)/100,0)*100,IF(ISNUMBER(C23),ROUND(C23*$B$4/100,0)*100,"")) -> 8800 | H23: 4.76 | I23: 2009 | J23: Image | K23: Produit
A24: cheveux | B24: Pantene Pro-V Ultimate Care 3-in-1 Shampoo, 38.2 fl. oz. | C24: 7.98 | F24: introuvable | G24: =IF(ISNUMBER(D24),ROUND(D24*(1-$B$3)/100,0)*100,IF(ISNUMBER(C24),ROUND(C24*$B$4/100,0)*100,"")) -> 8800 | H24: 4.77 | I24: 2258 | J24: Image | K24: Produit
A25: cheveux | B25: TRESemmé Ultimate Moisture Shampoo & Conditioner, 39 fl. oz., 2 pk. | C25: 11.98 | F25: introuvable | G25: =IF(ISNUMBER(D25),ROUND(D25*(1-$B$3)/100,0)*100,IF(ISNUMBER(C25),ROUND(C25*$B$4/100,0)*100,"")) -> 13200 | H25: 4.64 | I25: 455 | J25: Image | K25: Produit
A26: cheveux | B26: The LaserBand 41 ComfortFlex Hair Growth Bundle | C26: 494.25 | F26: introuvable | G26: =IF(ISNUMBER(D26),ROUND(D26*(1-$B$3)/100,0)*100,IF(ISNUMBER(C26),ROUND(C26*$B$4/100,0)*100,"")) -> 543700 | H26: 5 | I26: 2 | J26: Image | K26: Produit
A27: corps & bain | B27: Aquaphor Advanced Therapy Healing Ointment Dual Pack | C27: 16.97 | D27: 14500 | E27: Voir | F27: similaire | G27: =IF(ISNUMBER(D27),ROUND(D27*(1-$B$3)/100,0)*100,IF(ISNUMBER(C27),ROUND(C27*$B$4/100,0)*100,"")) -> 13800 | H27: 4.73 | I27: 71 | J27: Image | K27: Produit
A28: corps & bain | B28: Aveeno Daily Moisturizing Body Lotion Set | C28: 16.48 | D28: 16000 | E28: Voir | F28: similaire | G28: =IF(ISNUMBER(D28),ROUND(D28*(1-$B$3)/100,0)*100,IF(ISNUMBER(C28),ROUND(C28*$B$4/100,0)*100,"")) -> 15200 | H28: 4.76 | I28: 5729 | J28: Image | K28: Produit
A29: corps & bain | B29: Caress Daily Silk Hydrating Body Wash, White Peach & Orange Blossom, 30 fl. oz., 2 pk. | C29: 11.96 | F29: introuvable | G29: =IF(ISNUMBER(D29),ROUND(D29*(1-$B$3)/100,0)*100,IF(ISNUMBER(C29),ROUND(C29*$B$4/100,0)*100,"")) -> 13200 | H29: 4.69 | I29: 1572 | J29: Image | K29: Produit
A30: corps & bain | B30: CeraVe Daily Moisturizing Cream Multi-Pack | C30: 22.76 | D30: 14000 | E30: Voir | F30: similaire | G30: =IF(ISNUMBER(D30),ROUND(D30*(1-$B$3)/100,0)*100,IF(ISNUMBER(C30),ROUND(C30*$B$4/100,0)*100,"")) -> 13300 | H30: 4.84 | I30: 488 | J30: Image | K30: Produit
A31: corps & bain | B31: CeraVe Daily Moisturizing Lotion, Normal to Dry Skin, 12 fl. oz., 2 pk. | C31: Prix membre | D31: 10000 | E31: Voir | F31: similaire | G31: =IF(ISNUMBER(D31),ROUND(D31*(1-$B$3)/100,0)*100,IF(ISNUMBER(C31),ROUND(C31*$B$4/100,0)*100,"")) -> 9500 | H31: 4.77 | I31: 391 | J31: Image | K31: Produit
A32: corps & bain | B32: Dove Beauty Bar Soap, Original White, 3.75 oz., 16 ct. | C32: 18.48 | D32: 1000 | E32: Voir | F32: similaire | G32: =IF(ISNUMBER(D32),ROUND(D32*(1-$B$3)/100,0)*100,IF(ISNUMBER(C32),ROUND(C32*$B$4/100,0)*100,"")) -> 1000 | H32: 4.77 | I32: 103 | J32: Image | K32: Produit
A33: corps & bain | B33: Dove Beauty Bar Soap, Sensitive Skin, 3.75 oz., 16 ct. | C33: 18.48 | D33: 1000 | E33: Voir | F33: similaire | G33: =IF(ISNUMBER(D33),ROUND(D33*(1-$B$3)/100,0)*100,IF(ISNUMBER(C33),ROUND(C33*$B$4/100,0)*100,"")) -> 1000 | H33: 4.72 | I33: 8057 | J33: Image | K33: Produit
A34: corps & bain | B34: Dove Deep Moisture Body Wash with Pump, 30.6 fl. oz., 2 ct. | C34: 16.48 | D34: 7950 | E34: Voir | F34: similaire | G34: =IF(ISNUMBER(D34),ROUND(D34*(1-$B$3)/100,0)*100,IF(ISNUMBER(C34),ROUND(C34*$B$4/100,0)*100,"")) -> 7600 | H34: 4.8 | I34: 1348 | J34: Image | K34: Produit
A35: corps & bain | B35: Dove Men+Care Sandalwood Body Wash, 26 fl. oz., 2 pk. | C35: 14.98 | D35: 2000 | E35: Voir | F35: similaire | G35: =IF(ISNUMBER(D35),ROUND(D35*(1-$B$3)/100,0)*100,IF(ISNUMBER(C35),ROUND(C35*$B$4/100,0)*100,"")) -> 1900 | H35: 4.58 | I35: 214 | J35: Image | K35: Produit
A36: corps & bain | B36: Dove Pamper & Anti-Stress Body Wash, 30.6 fl. oz., 2 pk. | C36: 16.48 | D36: 9900 | E36: Voir | F36: similaire | G36: =IF(ISNUMBER(D36),ROUND(D36*(1-$B$3)/100,0)*100,IF(ISNUMBER(C36),ROUND(C36*$B$4/100,0)*100,"")) -> 9400 | H36: 4.57 | I36: 126 | J36: Image | K36: Produit
A37: corps & bain | B37: Dove Sensitive Skin Body Wash with Pump, 30.6 fl. oz., 2 ct. | C37: 16.48 | D37: 7950 | E37: Voir | F37: similaire | G37: =IF(ISNUMBER(D37),ROUND(D37*(1-$B$3)/100,0)*100,IF(ISNUMBER(C37),ROUND(C37*$B$4/100,0)*100,"")) -> 7600 | H37: 4.78 | I37: 1603 | J37: Image | K37: Produit
A38: corps & bain | B38: Irish Spring Body Wash for Men, Original Clean, 30 fl. oz., 2 pk. | C38: 10.96 | D38: 1400 | E38: Voir | F38: similaire | G38: =IF(ISNUMBER(D38),ROUND(D38*(1-$B$3)/100,0)*100,IF(ISNUMBER(C38),ROUND(C38*$B$4/100,0)*100,"")) -> 1300 | H38: 4.69 | I38: 1165 | J38: Image | K38: Produit
A39: corps & bain | B39: Member's Mark Aloe Vera Moisturizing Hand Soap, 80 fl. oz. | C39: 7.98 | F39: introuvable | G39: =IF(ISNUMBER(D39),ROUND(D39*(1-$B$3)/100,0)*100,IF(ISNUMBER(C39),ROUND(C39*$B$4/100,0)*100,"")) -> 8800 | H39: 4.56 | I39: 6383 | J39: Image | K39: Produit
A40: corps & bain | B40: Neutrogena Rainbath Refreshing Shower and Bath Gel, Original, 40 fl. oz. | C40: Prix membre | F40: introuvable | G40: =IF(ISNUMBER(D40),ROUND(D40*(1-$B$3)/100,0)*100,IF(ISNUMBER(C40),ROUND(C40*$B$4/100,0)*100,"")) | H40: 4.82 | I40: 2537 | J40: Image | K40: Produit
A41: corps & bain | B41: Nutrius Brazilian Body Butter Cream, 12 fl. oz. | C41: 16.98 | F41: introuvable | G41: =IF(ISNUMBER(D41),ROUND(D41*(1-$B$3)/100,0)*100,IF(ISNUMBER(C41),ROUND(C41*$B$4/100,0)*100,"")) -> 18700 | J41: Image | K41: Produit
...

Sheet Synthèse
A1: Synthèse
A3: Produits total | B3: =COUNTA(Produits!B7:B165) -> 159
A4: Avec prix Dakar (bench) | B4: =COUNT(Produits!D7:D165) -> 71
A5: Match exact | B5: =COUNTIF(Produits!F:F,"exact") -> 5
A6: Match similaire | B6: =COUNTIF(Produits!F:F,"similaire") -> 72
A7: Introuvables à Dakar | B7: =COUNTIF(Produits!F:F,"introuvable") -> 82
